<?xml version="1.0" encoding="UTF-8"?>
<testng-results skipped="0" failed="2" ignored="0" total="4" passed="2">
  <reporter-output>
    <line>
      <![CDATA[Expected text value 'Bob' but was 'John' - comparing <firstName ...>Bob</firstName> at /customer[1]/firstName[1]/text()[1] to <firstName ...>John</firstName> at /customer[1]/firstName[1]/text()[1] (DIFFERENT)]]>
    </line>
    <line>
      <![CDATA[ValidationProblem { line=22, column=12, type=ERROR, message='cvc-complex-type.2.4.a: Invalid content was found starting with element 'price'. One of '{note, quantity}' is expected.' }]]>
    </line>
  </reporter-output>
  <suite name="Default suite" duration-ms="1096" started-at="2018-08-06T12:42:02Z" finished-at="2018-08-06T12:42:03Z">
    <groups>
    </groups>
    <test name="Default test" duration-ms="1096" started-at="2018-08-06T12:42:02Z" finished-at="2018-08-06T12:42:03Z">
      <class name="com.ontestautomation.xmlunit.XmlUnitTest">
        <test-method status="PASS" signature="init()[pri:0, instance:com.ontestautomation.xmlunit.XmlUnitTest@51a6cc2a]" name="init" is-config="true" duration-ms="30" started-at="2018-08-06T12:42:02Z" finished-at="2018-08-06T12:42:02Z">
          <reporter-output>
          </reporter-output>
        </test-method> <!-- init -->
        <test-method status="PASS" signature="aFirstTest()[pri:0, instance:com.ontestautomation.xmlunit.XmlUnitTest@51a6cc2a]" name="aFirstTest" duration-ms="55" started-at="2018-08-06T12:42:02Z" finished-at="2018-08-06T12:42:02Z">
          <reporter-output>
          </reporter-output>
        </test-method> <!-- aFirstTest -->
        <test-method status="FAIL" signature="compareTest()[pri:0, instance:com.ontestautomation.xmlunit.XmlUnitTest@51a6cc2a]" name="compareTest" duration-ms="657" started-at="2018-08-06T12:42:02Z" finished-at="2018-08-06T12:42:02Z">
          <exception class="java.lang.AssertionError">
            <message>
              <![CDATA[expected [false] but found [true]]]>
            </message>
            <full-stacktrace>
              <![CDATA[java.lang.AssertionError: expected [false] but found [true]
at org.testng.Assert.fail(Assert.java:96)
at org.testng.Assert.failNotEquals(Assert.java:776)
at org.testng.Assert.assertEqualsImpl(Assert.java:137)
at org.testng.Assert.assertEquals(Assert.java:118)
at org.testng.Assert.assertEquals(Assert.java:568)
at org.testng.Assert.assertEquals(Assert.java:578)
at com.ontestautomation.xmlunit.XmlUnitTest.compareTest(XmlUnitTest.java:62)
at sun.reflect.NativeMethodAccessorImpl.invoke0(Native Method)
at sun.reflect.NativeMethodAccessorImpl.invoke(Unknown Source)
at sun.reflect.DelegatingMethodAccessorImpl.invoke(Unknown Source)
at java.lang.reflect.Method.invoke(Unknown Source)
at org.testng.internal.MethodInvocationHelper.invokeMethod(MethodInvocationHelper.java:124)
at org.testng.internal.Invoker.invokeMethod(Invoker.java:580)
at org.testng.internal.Invoker.invokeTestMethod(Invoker.java:716)
at org.testng.internal.Invoker.invokeTestMethods(Invoker.java:988)
at org.testng.internal.TestMethodWorker.invokeTestMethods(TestMethodWorker.java:125)
at org.testng.internal.TestMethodWorker.run(TestMethodWorker.java:109)
at org.testng.TestRunner.privateRun(TestRunner.java:648)
at org.testng.TestRunner.run(TestRunner.java:505)
at org.testng.SuiteRunner.runTest(SuiteRunner.java:455)
at org.testng.SuiteRunner.runSequentially(SuiteRunner.java:450)
at org.testng.SuiteRunner.privateRun(SuiteRunner.java:415)
at org.testng.SuiteRunner.run(SuiteRunner.java:364)
at org.testng.SuiteRunnerWorker.runSuite(SuiteRunnerWorker.java:52)
at org.testng.SuiteRunnerWorker.run(SuiteRunnerWorker.java:84)
at org.testng.TestNG.runSuitesSequentially(TestNG.java:1208)
at org.testng.TestNG.runSuitesLocally(TestNG.java:1137)
at org.testng.TestNG.runSuites(TestNG.java:1049)
at org.testng.TestNG.run(TestNG.java:1017)
at org.testng.remote.AbstractRemoteTestNG.run(AbstractRemoteTestNG.java:114)
at org.testng.remote.RemoteTestNG.initAndRun(RemoteTestNG.java:251)
at org.testng.remote.RemoteTestNG.main(RemoteTestNG.java:77)
]]>
            </full-stacktrace>
          </exception> <!-- java.lang.AssertionError -->
          <reporter-output>
            <line>
              <![CDATA[Expected text value 'Bob' but was 'John' - comparing <firstName ...>Bob</firstName> at /customer[1]/firstName[1]/text()[1] to <firstName ...>John</firstName> at /customer[1]/firstName[1]/text()[1] (DIFFERENT)]]>
            </line>
          </reporter-output>
        </test-method> <!-- compareTest -->
        <test-method status="PASS" signature="restCallTest()[pri:0, instance:com.ontestautomation.xmlunit.XmlUnitTest@51a6cc2a]" name="restCallTest" duration-ms="256" started-at="2018-08-06T12:42:02Z" finished-at="2018-08-06T12:42:03Z">
          <reporter-output>
          </reporter-output>
        </test-method> <!-- restCallTest -->
        <test-method status="FAIL" signature="validationTest()[pri:0, instance:com.ontestautomation.xmlunit.XmlUnitTest@51a6cc2a]" name="validationTest" duration-ms="70" started-at="2018-08-06T12:42:03Z" finished-at="2018-08-06T12:42:03Z">
          <exception class="java.lang.AssertionError">
            <message>
              <![CDATA[expected [true] but found [false]]]>
            </message>
            <full-stacktrace>
              <![CDATA[java.lang.AssertionError: expected [true] but found [false]
at org.testng.Assert.fail(Assert.java:96)
at org.testng.Assert.failNotEquals(Assert.java:776)
at org.testng.Assert.assertEqualsImpl(Assert.java:137)
at org.testng.Assert.assertEquals(Assert.java:118)
at org.testng.Assert.assertEquals(Assert.java:568)
at org.testng.Assert.assertEquals(Assert.java:578)
at com.ontestautomation.xmlunit.XmlUnitTest.validationTest(XmlUnitTest.java:78)
at sun.reflect.NativeMethodAccessorImpl.invoke0(Native Method)
at sun.reflect.NativeMethodAccessorImpl.invoke(Unknown Source)
at sun.reflect.DelegatingMethodAccessorImpl.invoke(Unknown Source)
at java.lang.reflect.Method.invoke(Unknown Source)
at org.testng.internal.MethodInvocationHelper.invokeMethod(MethodInvocationHelper.java:124)
at org.testng.internal.Invoker.invokeMethod(Invoker.java:580)
at org.testng.internal.Invoker.invokeTestMethod(Invoker.java:716)
at org.testng.internal.Invoker.invokeTestMethods(Invoker.java:988)
at org.testng.internal.TestMethodWorker.invokeTestMethods(TestMethodWorker.java:125)
at org.testng.internal.TestMethodWorker.run(TestMethodWorker.java:109)
at org.testng.TestRunner.privateRun(TestRunner.java:648)
at org.testng.TestRunner.run(TestRunner.java:505)
at org.testng.SuiteRunner.runTest(SuiteRunner.java:455)
at org.testng.SuiteRunner.runSequentially(SuiteRunner.java:450)
at org.testng.SuiteRunner.privateRun(SuiteRunner.java:415)
at org.testng.SuiteRunner.run(SuiteRunner.java:364)
at org.testng.SuiteRunnerWorker.runSuite(SuiteRunnerWorker.java:52)
at org.testng.SuiteRunnerWorker.run(SuiteRunnerWorker.java:84)
at org.testng.TestNG.runSuitesSequentially(TestNG.java:1208)
at org.testng.TestNG.runSuitesLocally(TestNG.java:1137)
at org.testng.TestNG.runSuites(TestNG.java:1049)
at org.testng.TestNG.run(TestNG.java:1017)
at org.testng.remote.AbstractRemoteTestNG.run(AbstractRemoteTestNG.java:114)
at org.testng.remote.RemoteTestNG.initAndRun(RemoteTestNG.java:251)
at org.testng.remote.RemoteTestNG.main(RemoteTestNG.java:77)
]]>
            </full-stacktrace>
          </exception> <!-- java.lang.AssertionError -->
          <reporter-output>
            <line>
              <![CDATA[ValidationProblem { line=22, column=12, type=ERROR, message='cvc-complex-type.2.4.a: Invalid content was found starting with element 'price'. One of '{note, quantity}' is expected.' }]]>
            </line>
          </reporter-output>
        </test-method> <!-- validationTest -->
      </class> <!-- com.ontestautomation.xmlunit.XmlUnitTest -->
    </test> <!-- Default test -->
  </suite> <!-- Default suite -->
</testng-results>
